Workbook
Name ___1__123Graph_A圖表_1: '[1]X-R CHART'!$C$46:$AG$46
Name ___2__123Graph_A圖表_2: '[1]X-R CHART'!$C$49:$AG$49
Name ___3__123Graph_B圖表_1: '[1]X-R CHART'!$C$47:$AG$47
Name ___4__123Graph_B圖表_2: '[1]X-R CHART'!$C$50:$AG$50
Name ___5__123Graph_C圖表_1: '[1]X-R CHART'!$C$48:$AG$48
Name ___6__123Graph_C圖表_2: '[1]X-R CHART'!$C$51:$AG$51
Name ___7__123Graph_D圖表_1: '[1]X-R CHART'!$C$16:$M$16
Name ___8__123Graph_D圖表_2: '[1]X-R CHART'!$C$17:$AG$17
Name __1__123Graph_A圖表_1: '[1]X-R CHART'!$C$46:$AG$46
Name __2__123Graph_A圖表_2: '[1]X-R CHART'!$C$49:$AG$49
Name __3__123Graph_B圖表_1: '[1]X-R CHART'!$C$47:$AG$47
Name __4__123Graph_B圖表_2: '[1]X-R CHART'!$C$50:$AG$50
Name __5__123Graph_C圖表_1: '[1]X-R CHART'!$C$48:$AG$48
Name __6__123Graph_C圖表_2: '[1]X-R CHART'!$C$51:$AG$51
Name __7__123Graph_D圖表_1: '[1]X-R CHART'!$C$16:$M$16
Name __8__123Graph_D圖表_2: '[1]X-R CHART'!$C$17:$AG$17
Name _1__123Graph_A圖表_1: '[1]X-R CHART'!$C$46:$AG$46
Name _2__123Graph_A圖表_2: '[1]X-R CHART'!$C$49:$AG$49
Name _3__123Graph_B圖表_1: '[1]X-R CHART'!$C$47:$AG$47
Name _4__123Graph_B圖表_2: '[1]X-R CHART'!$C$50:$AG$50
Name _5__123Graph_C圖表_1: '[1]X-R CHART'!$C$48:$AG$48
Name _6__123Graph_C圖表_2: '[1]X-R CHART'!$C$51:$AG$51
Name _7__123Graph_D圖表_1: '[1]X-R CHART'!$C$16:$M$16
Name _8__123Graph_D圖表_2: '[1]X-R CHART'!$C$17:$AG$17
Name group: {#N/A,#N/A,FALSE,"FA Approval Report ";#N/A,#N/A,FALSE,"FA Data Sheet Full dimension";#N/A,#N/A,FALSE,"FA Data Sheet Cpk"}
Name Group1: {#N/A,#N/A,FALSE,"FA Approval Report ";#N/A,#N/A,FALSE,"FA Data Sheet Full dimension";#N/A,#N/A,FALSE,"FA Data Sheet Cpk"}
Name Group4: {#N/A,#N/A,FALSE,"FA Approval Report ";#N/A,#N/A,FALSE,"FA Data Sheet Full dimension";#N/A,#N/A,FALSE,"FA Data Sheet Cpk"}
Name wrn.FA._.Report.: {#N/A,#N/A,FALSE,"FA Approval Report ";#N/A,#N/A,FALSE,"FA Data Sheet Full dimension";#N/A,#N/A,FALSE,"FA Data Sheet Cpk"}
Name 区分: #REF!

Sheet dcr
P1: when submit, please delete these info
D2: RGO NET name and pin assign | I2: ERS spec | L2: 3 sigma spec | N2: On machine | P2: our jig pin No correlated with RGO assignment | AZ2: Measured Value
D3: Net name | E3: pin1 | G3: pin2 | I3: Nominal | J3: LSL | K3: USL | L3: LSL | M3: USL | N3: LSL | O3: USL | P3: Gr1 | T3: Gr2 | X3: Gr3 | AB3: Gr4 | AF3: Gr5 | AJ3: Gr6 | AN3: Gr7 | AR3: Gr8 | AV3: Gr9 | AZ3: 1 | BA3: 2 | BB3: 3 | BC3: 4 | BD3: 5 | BE3: 6 | BF3: 7 | BG3: 8 | BH3: 9 | BI3: 10 | BJ3: 11 | BK3: 12 | BL3: 13 | BM3: 14 | BN3: 15 | BO3: 16 | BP3: 17 | BQ3: 18 | BR3: 19 | BS3: 20 | BT3: 21 | BU3: 22 | BV3: 23 | BW3: 24 | BX3: 25 | BY3: 26 | BZ3: 27 | CA3: 28 | CB3: 29 | CC3: 30 | CD3: 31 | CE3: 32 | CF3: 33 | CG3: 34 | CH3: 35 | CI3: 36 | CJ3: 37 | CK3: 38 | CL3: 39 | CM3: 40 | CN3: 41 | CO3: 42 | CP3: 43 | CQ3: 44 | CR3: 45 | CS3: 46 | CT3: 47 | CU3: 48 | CV3: 49 | CW3: 50 | CX3: 51 | CY3: 52 | CZ3: 53 | DA3: 54 | DB3: 55 | DC3: 56 | DD3: 57 | DE3: 58 | DF3: 59 | DG3: 60 | DH3: 61 | DI3: 62 | DJ3: 63 | DK3: 64 | DL3: 65 | DM3: 66 | DN3: 67 | DO3: 68 | DP3: 69 | DQ3: 70 | DR3: 71 | DS3: 72 | DT3: 73 | DU3: 74 | DV3: 75 | DW3: 76 | DX3: 77 | DY3: 78 | DZ3: 79 | EA3: 80 | EB3: 81 | EC3: 82 | ED3: 83 | EE3: 84 | EF3: 85 | EG3: 86 | EH3: 87 | EI3: 88 | EJ3: 89 | EK3: 90 | EL3: 91 | EM3: 92 | EN3: 93 | EO3: 94 | EP3: 95 | EQ3: 96 | ER3: 97 | ES3: 98 | ET3: 99 | EU3: 100
A4: =Q4&S4 -> 205050 | B4: =E4&"."&F4&G4&"."&H4 -> J_TELE.1U0200.25 | C4: 1 | D4: PPVAR_TELE_PVDD_AF_CONN | E4: J_TELE | F4: 1 | G4: U0200 | H4: 25 | I4: =VLOOKUP(B4, vendor!$A$10:$Q$28,15,0) -> 223.75133 | J4: =VLOOKUP(B4, vendor!$A$10:$Q$28,17,0) -> 162.7715 | K4: =VLOOKUP(B4, vendor!$A$10:$Q$28,16,0) -> 315.4005 | L4: 218 | M4: 247 | N4: 218 | O4: 247 | P4: 2049 | Q4: 2050 | R4: 49 | S4: 50 | T4: 2099 | U4: 2100 | V4: 119 | W4: 120 | X4: 2149 | Y4: 2150 | Z4: 189 | AA4: 190 | AB4: 2199 | AC4: 2200 | AD4: 259 | AE4: 260 | AF4: 2249 | AG4: 2250 | AH4: 329 | AI4: 330 | AJ4: 2299 | AK4: 2300 | AL4: 399 | AM4: 400 | AN4: 2349 | AO4: 2350 | AP4: 469 | AQ4: 470 | AR4: 3073 | AS4: 3074 | AT4: 1073 | AU4: 1074 | AV4: 3123 | AW4: 3124 | AX4: 1143 | AY4: 1144 | AZ4: 3173 | BA4: 3174 | BB4: 1213 | BC4: 1214 | BD4: 3223 | BE4: 3224 | BF4: 1283 | BG4: 1284 | BH4: 3273 | BI4: 3274 | BJ4: 1353 | BK4: 1354 | BL4: 3323 | BM4: 3324 | BN4: 1423 | BO4: 1424 | BP4: 3373 | BQ4: 3374 | BR4: 1493 | BS4: 1494
A5: =Q5&S5 -> 205244 | B5: =E5&"."&F5&G5&"."&H5 -> J_TELE.2U0200.22 | C5: 2 | D5: I2C0_CAM_PMU2_SCL_1V8 | E5: J_TELE | F5: 2 | G5: U0200 | H5: 22 | I5: =VLOOKUP(B5, vendor!$A$10:$Q$28,15,0) -> 1974.0056 | J5: =VLOOKUP(B5, vendor!$A$10:$Q$28,17,0) -> 1226.8341 | K5: =VLOOKUP(B5, vendor!$A$10:$Q$28,16,0) -> 3547.1402 | L5: 1603 | M5: 2642 | N5: 1603 | O5: 2642 | P5: 2051 | Q5: 2052 | R5: 43 | S5: 44 | T5: 2101 | U5: 2102 | V5: 113 | W5: 114 | X5: 2151 | Y5: 2152 | Z5: 183 | AA5: 184 | AB5: 2201 | AC5: 2202 | AD5: 253 | AE5: 254 | AF5: 2251 | AG5: 2252 | AH5: 323 | AI5: 324 | AJ5: 2301 | AK5: 2302 | AL5: 393 | AM5: 394 | AN5: 2351 | AO5: 2352 | AP5: 463 | AQ5: 464 | AR5: 3075 | AS5: 3076 | AT5: 1067 | AU5: 1068 | AV5: 3125 | AW5: 3126 | AX5: 1137 | AY5: 1138 | AZ5: 3175 | BA5: 3176 | BB5: 1207 | BC5: 1208 | BD5: 3225 | BE5: 3226 | BF5: 1277 | BG5: 1278 | BH5: 3275 | BI5: 3276 | BJ5: 1347 | BK5: 1348 | BL5: 3325 | BM5: 3326 | BN5: 1417 | BO5: 1418 | BP5: 3375 | BQ5: 3376 | BR5: 1487 | BS5: 1488
A6: =Q6&S6 -> 205448 | B6: =E6&"."&F6&G6&"."&H6 -> J_TELE.3U0200.24 | C6: 3 | D6: PP1V91_TELE_VDDIO_CONN | E6: J_TELE | F6: 3 | G6: U0200 | H6: 24 | I6: =VLOOKUP(B6, vendor!$A$10:$Q$28,15,0) -> 1244.3811 | J6: =VLOOKUP(B6, vendor!$A$10:$Q$28,17,0) -> 780.91931 | K6: =VLOOKUP(B6, vendor!$A$10:$Q$28,16,0) -> 2167.6864 | L6: 1115 | M6: 1503 | N6: 1115 | O6: 1503 | P6: 2053 | Q6: 2054 | R6: 47 | S6: 48 | T6: 2103 | U6: 2104 | V6: 117 | W6: 118 | X6: 2153 | Y6: 2154 | Z6: 187 | AA6: 188 | AB6: 2203 | AC6: 2204 | AD6: 257 | AE6: 258 | AF6: 2253 | AG6: 2254 | AH6: 327 | AI6: 328 | AJ6: 2303 | AK6: 2304 | AL6: 397 | AM6: 398 | AN6: 2353 | AO6: 2354 | AP6: 467 | AQ6: 468 | AR6: 3077 | AS6: 3078 | AT6: 1071 | AU6: 1072 | AV6: 3127 | AW6: 3128 | AX6: 1141 | AY6: 1142 | AZ6: 3177 | BA6: 3178 | BB6: 1211 | BC6: 1212 | BD6: 3227 | BE6: 3228 | BF6: 1281 | BG6: 1282 | BH6: 3277 | BI6: 3278 | BJ6: 1351 | BK6: 1352 | BL6: 3327 | BM6: 3328 | BN6: 1421 | BO6: 1422 | BP6: 3377 | BQ6: 3378 | BR6: 1491 | BS6: 1492
A7: =Q7&S7 -> 205846 | B7: =E7&"."&F7&G7&"."&H7 -> J_TELE.5U0200.23 | C7: 4 | D7: I2C0_CAM_PMU2_SDA_1V8 | E7: J_TELE | F7: 5 | G7: U0200 | H7: 23 | I7: =VLOOKUP(B7, vendor!$A$10:$Q$28,15,0) -> 2033.4002 | J7: =VLOOKUP(B7, vendor!$A$10:$Q$28,17,0) -> 1262.9662 | K7: =VLOOKUP(B7, vendor!$A$10:$Q$28,16,0) -> 3655.3378 | L7: 1646 | M7: 2717 | N7: 1646 | O7: 2717 | P7: 2057 | Q7: 2058 | R7: 45 | S7: 46 | T7: 2107 | U7: 2108 | V7: 115 | W7: 116 | X7: 2157 | Y7: 2158 | Z7: 185 | AA7: 186 | AB7: 2207 | AC7: 2208 | AD7: 255 | AE7: 256 | AF7: 2257 | AG7: 2258 | AH7: 325 | AI7: 326 | AJ7: 2307 | AK7: 2308 | AL7: 395 | AM7: 396 | AN7: 2357 | AO7: 2358 | AP7: 465 | AQ7: 466 | AR7: 3081 | AS7: 3082 | AT7: 1069 | AU7: 1070 | AV7: 3131 | AW7: 3132 | AX7: 1139 | AY7: 1140 | AZ7: 3181 | BA7: 3182 | BB7: 1209 | BC7: 1210 | BD7: 3231 | BE7: 3232 | BF7: 1279 | BG7: 1280 | BH7: 3281 | BI7: 3282 | BJ7: 1349 | BK7: 1350 | BL7: 3331 | BM7: 3332 | BN7: 1419 | BO7: 1420 | BP7: 3381 | BQ7: 3382 | BR7: 1489 | BS7: 1490
A8: =Q8&S8 -> 206028 | B8: =E8&"."&F8&G8&"."&H8 -> J_TELE.6U0200.14 | C8: 5 | D8: 85_LPDP_ISP_FROM_TELE_RX_D2_CONN_N | E8: J_TELE | F8: 6 | G8: U0200 | H8: 14 | I8: =VLOOKUP(B8, vendor!$A$10:$Q$28,15,0) -> 1934.3551 | J8: =VLOOKUP(B8, vendor!$A$10:$Q$28,17,0) -> 1202.784 | K8: =VLOOKUP(B8, vendor!$A$10:$Q$28,16,0) -> 3488.5586 | L8: 1551 | M8: 2705 | N8: 1551 | O8: 2705 | P8: 2059 | Q8: 2060 | R8: 27 | S8: 28 | T8: 2109 | U8: 2110 | V8: 97 | W8: 98 | X8: 2159 | Y8: 2160 | Z8: 167 | AA8: 168 | AB8: 2209 | AC8: 2210 | AD8: 237 | AE8: 238 | AF8: 2259 | AG8: 2260 | AH8: 307 | AI8: 308 | AJ8: 2309 | AK8: 2310 | AL8: 377 | AM8: 378 | AN8: 2359 | AO8: 2360 | AP8: 447 | AQ8: 448 | AR8: 3083 | AS8: 3084 | AT8: 1051 | AU8: 1052 | AV8: 3133 | AW8: 3134 | AX8: 1121 | AY8: 1122 | AZ8: 3183 | BA8: 3184 | BB8: 1191 | BC8: 1192 | BD8: 3233 | BE8: 3234 | BF8: 1261 | BG8: 1262 | BH8: 3283 | BI8: 3284 | BJ8: 1331 | BK8: 1332 | BL8: 3333 | BM8: 3334 | BN8: 1401 | BO8: 1402 | BP8: 3383 | BQ8: 3384 | BR8: 1471 | BS8: 1472
A9: =Q9&S9 -> 206240 | B9: =E9&"."&F9&G9&"."&H9 -> J_TELE.7U0200.20 | C9: 6 | D9: PP2V33_TELE_AVDD2_CONN | E9: J_TELE | F9: 7 | G9: U0200 | H9: 20 | I9: =VLOOKUP(B9, vendor!$A$10:$Q$28,15,0) -> 809.44327 | J9: =VLOOKUP(B9, vendor!$A$10:$Q$28,17,0) -> 510.61888 | K9: =VLOOKUP(B9, vendor!$A$10:$Q$28,16,0) -> 1386.1815 | L9: 761 | M9: 934 | N9: 761 | O9: 934 | P9: 2061 | Q9: 2062 | R9: 39 | S9: 40 | T9: 2111 | U9: 2112 | V9: 109 | W9: 110 | X9: 2161 | Y9: 2162 | Z9: 179 | AA9: 180 | AB9: 2211 | AC9: 2212 | AD9: 249 | AE9: 250 | AF9: 2261 | AG9: 2262 | AH9: 319 | AI9: 320 | AJ9: 2311 | AK9: 2312 | AL9: 389 | AM9: 390 | AN9: 2361 | AO9: 2362 | AP9: 459 | AQ9: 460 | AR9: 3085 | AS9: 3086 | AT9: 1063 | AU9: 1064 | AV9: 3135 | AW9: 3136 | AX9: 1133 | AY9: 1134 | AZ9: 3185 | BA9: 3186 | BB9: 1203 | BC9: 1204 | BD9: 3235 | BE9: 3236 | BF9: 1273 | BG9: 1274 | BH9: 3285 | BI9: 3286 | BJ9: 1343 | BK9: 1344 | BL9: 3335 | BM9: 3336 | BN9: 1413 | BO9: 1414 | BP9: 3385 | BQ9: 3386 | BR9: 1483 | BS9: 1484
A10: =Q10&S10 -> 206426 | B10: =E10&"."&F10&G10&"."&H10 -> J_TELE.8U0200.13 | C10: 7 | D10: 85_LPDP_ISP_FROM_TELE_RX_D2_CONN_P | E10: J_TELE | F10: 8 | G10: U0200 | H10: 13 | I10: =VLOOKUP(B10, vendor!$A$10:$Q$28,15,0) -> 1933.6592 | J10: =VLOOKUP(B10, vendor!$A$10:$Q$28,17,0) -> 1202.4945 | K10: =VLOOKUP(B10, vendor!$A$10:$Q$28,16,0) -> 3486.518 | L10: 1552 | M10: 2705 | N10: 1552 | O10: 2705 | P10: 2063 | Q10: 2064 | R10: 25 | S10: 26 | T10: 2113 | U10: 2114 | V10: 95 | W10: 96 | X10: 2163 | Y10: 2164 | Z10: 165 | AA10: 166 | AB10: 2213 | AC10: 2214 | AD10: 235 | AE10: 236 | AF10: 2263 | AG10: 2264 | AH10: 305 | AI10: 306 | AJ10: 2313 | AK10: 2314 | AL10: 375 | AM10: 376 | AN10: 2363 | AO10: 2364 | AP10: 445 | AQ10: 446 | AR10: 3087 | AS10: 3088 | AT10: 1049 | AU10: 1050 | AV10: 3137 | AW10: 3138 | AX10: 1119 | AY10: 1120 | AZ10: 3187 | BA10: 3188 | BB10: 1189 | BC10: 1190 | BD10: 3237 | BE10: 3238 | BF10: 1259 | BG10: 1260 | BH10: 3287 | BI10: 3288 | BJ10: 1329 | BK10: 1330 | BL10: 3337 | BM10: 3338 | BN10: 1399 | BO10: 1400 | BP10: 3387 | BQ10: 3388 | BR10: 1469 | BS10: 1470
A11: =Q11&S11 -> 206636 | B11: =E11&"."&F11&G11&"."&H11 -> J_TELE.9U0200.18 | C11: 8 | D11: PP3V2_TELE_AVDD1_CONN | E11: J_TELE | F11: 9 | G11: U0200 | H11: 18 | I11: =VLOOKUP(B11, vendor!$A$10:$Q$28,15,0) -> 324.65375 | J11: =VLOOKUP(B11, vendor!$A$10:$Q$28,17,0) -> 224.02925 | K11: =VLOOKUP(B11, vendor!$A$10:$Q$28,16,0) -> 495.21681 | L11: 314 | M11: 364 | N11: 314 | O11: 364 | P11: 2065 | Q11: 2066 | R11: 35 | S11: 36 | T11: 2115 | U11: 2116 | V11: 105 | W11: 106 | X11: 2165 | Y11: 2166 | Z11: 175 | AA11: 176 | AB11: 2215 | AC11: 2216 | AD11: 245 | AE11: 246 | AF11: 2265 | AG11: 2266 | AH11: 315 | AI11: 316 | AJ11: 2315 | AK11: 2316 | AL11: 385 | AM11: 386 | AN11: 2365 | AO11: 2366 | AP11: 455 | AQ11: 456 | AR11: 3089 | AS11: 3090 | AT11: 1059 | AU11: 1060 | AV11: 3139 | AW11: 3140 | AX11: 1129 | AY11: 1130 | AZ11: 3189 | BA11: 3190 | BB11: 1199 | BC11: 1200 | BD11: 3239 | BE11: 3240 | BF11: 1269 | BG11: 1270 | BH11: 3289 | BI11: 3290 | BJ11: 1339 | BK11: 1340 | BL11: 3339 | BM11: 3340 | BN11: 1409 | BO11: 1410 | BP11: 3389 | BQ11: 3390 | BR11: 1479 | BS11: 1480
A12: =Q12&S12 -> 206638 | B12: =E12&"."&F12&G12&"."&H12 -> J_TELE.9U0200.19 | C12: 9 | D12: PP3V2_TELE_AVDD1_CONN | E12: J_TELE | F12: 9 | G12: U0200 | H12: 19 | L12: 313 | M12: 364 | N12: 313 | O12: 364 | P12: 2065 | Q12: 2066 | R12: 37 | S12: 38 | T12: 2115 | U12: 2116 | V12: 107 | W12: 108 | X12: 2165 | Y12: 2166 | Z12: 177 | AA12: 178 | AB12: 2215 | AC12: 2216 | AD12: 247 | AE12: 248 | AF12: 2265 | AG12: 2266 | AH12: 317 | AI12: 318 | AJ12: 2315 | AK12: 2316 | AL12: 387 | AM12: 388 | AN12: 2365 | AO12: 2366 | AP12: 457 | AQ12: 458 | AR12: 3089 | AS12: 3090 | AT12: 1061 | AU12: 1062 | AV12: 3139 | AW12: 3140 | AX12: 1131 | AY12: 1132 | AZ12: 3189 | BA12: 3190 | BB12: 1201 | BC12: 1202 | BD12: 3239 | BE12: 3240 | BF12: 1271 | BG12: 1272 | BH12: 3289 | BI12: 3290 | BJ12: 1341 | BK12: 1342 | BL12: 3339 | BM12: 3340 | BN12: 1411 | BO12: 1412 | BP12: 3389 | BQ12: 3390 | BR12: 1481 | BS12: 1482
A13: =Q13&S13 -> 207032 | B13: =E13&"."&F13&G13&"."&H13 -> J_TELE.11U0200.16 | C13: 10 | D13: GPIO_CAMS_TO_STROBE_TRIGGER_1V8 | E13: J_TELE | F13: 11 | G13: U0200 | H13: 16 | I13: =VLOOKUP(B13, vendor!$A$10:$Q$28,15,0) -> 1968.1463 | J13: =VLOOKUP(B13, vendor!$A$10:$Q$28,17,0) -> 1222.6648 | K13: =VLOOKUP(B13, vendor!$A$10:$Q$28,16,0) -> 3534.787 | L13: 1580 | M13: 2643 | N13: 1580 | O13: 2643 | P13: 2069 | Q13: 2070 | R13: 31 | S13: 32 | T13: 2119 | U13: 2120 | V13: 101 | W13: 102 | X13: 2169 | Y13: 2170 | Z13: 171 | AA13: 172 | AB13: 2219 | AC13: 2220 | AD13: 241 | AE13: 242 | AF13: 2269 | AG13: 2270 | AH13: 311 | AI13: 312 | AJ13: 2319 | AK13: 2320 | AL13: 381 | AM13: 382 | AN13: 2369 | AO13: 2370 | AP13: 451 | AQ13: 452 | AR13: 3093 | AS13: 3094 | AT13: 1055 | AU13: 1056 | AV13: 3143 | AW13: 3144 | AX13: 1125 | AY13: 1126 | AZ13: 3193 | BA13: 3194 | BB13: 1195 | BC13: 1196 | BD13: 3243 | BE13: 3244 | BF13: 1265 | BG13: 1266 | BH13: 3293 | BI13: 3294 | BJ13: 1335 | BK13: 1336 | BL13: 3343 | BM13: 3344 | BN13: 1405 | BO13: 1406 | BP13: 3393 | BQ13: 3394 | BR13: 1475 | BS13: 1476
A14: =Q14&S14 -> 207222 | B14: =E14&"."&F14&G14&"."&H14 -> J_TELE.12U0200.11 | C14: 11 | D14: 85_LPDP_ISP_FROM_TELE_RX_D1_CONN_N | E14: J_TELE | F14: 12 | G14: U0200 | H14: 11 | I14: =VLOOKUP(B14, vendor!$A$10:$Q$28,15,0) -> 1907.3318 | J14: =VLOOKUP(B14, vendor!$A$10:$Q$28,17,0) -> 1185.7905 | K14: =VLOOKUP(B14, vendor!$A$10:$Q$28,16,0) -> 3441.1932 | L14: 1531 | M14: 2654 | N14: 1531 | O14: 2654 | P14: 2071 | Q14: 2072 | R14: 21 | S14: 22 | T14: 2121 | U14: 2122 | V14: 91 | W14: 92 | X14: 2171 | Y14: 2172 | Z14: 161 | AA14: 162 | AB14: 2221 | AC14: 2222 | AD14: 231 | AE14: 232 | AF14: 2271 | AG14: 2272 | AH14: 301 | AI14: 302 | AJ14: 2321 | AK14: 2322 | AL14: 371 | AM14: 372 | AN14: 2371 | AO14: 2372 | AP14: 441 | AQ14: 442 | AR14: 3095 | AS14: 3096 | AT14: 1045 | AU14: 1046 | AV14: 3145 | AW14: 3146 | AX14: 1115 | AY14: 1116 | AZ14: 3195 | BA14: 3196 | BB14: 1185 | BC14: 1186 | BD14: 3245 | BE14: 3246 | BF14: 1255 | BG14: 1256 | BH14: 3295 | BI14: 3296 | BJ14: 1325 | BK14: 1326 | BL14: 3345 | BM14: 3346 | BN14: 1395 | BO14: 1396 | BP14: 3395 | BQ14: 3396 | BR14: 1465 | BS14: 1466
A15: =Q15&S15 -> 20746 | B15: =E15&"."&F15&G15&"."&H15 -> J_TELE.13U0200.3 | C15: 12 | D15: GPIO_CAM_PMU1_TO_TELE_SHDN_1V8_L | E15: J_TELE | F15: 13 | G15: U0200 | H15: 3 | I15: =VLOOKUP(B15, vendor!$A$10:$Q$28,15,0) -> 2001.9336 | J15: =VLOOKUP(B15, vendor!$A$10:$Q$28,17,0) -> 1244.4436 | K15: =VLOOKUP(B15, vendor!$A$10:$Q$28,16,0) -> 3592.6463 | L15: 1630 | M15: 2682 | N15: 1630 | O15: 2682 | P15: 2073 | Q15: 2074 | R15: 5 | S15: 6 | T15: 2123 | U15: 2124 | V15: 75 | W15: 76 | X15: 2173 | Y15: 2174 | Z15: 145 | AA15: 146 | AB15: 2223 | AC15: 2224 | AD15: 215 | AE15: 216 | AF15: 2273 | AG15: 2274 | AH15: 285 | AI15: 286 | AJ15: 2323 | AK15: 2324 | AL15: 355 | AM15: 356 | AN15: 2373 | AO15: 2374 | AP15: 425 | AQ15: 426 | AR15: 3097 | AS15: 3098 | AT15: 1029 | AU15: 1030 | AV15: 3147 | AW15: 3148 | AX15: 1099 | AY15: 1100 | AZ15: 3197 | BA15: 3198 | BB15: 1169 | BC15: 1170 | BD15: 3247 | BE15: 3248 | BF15: 1239 | BG15: 1240 | BH15: 3297 | BI15: 3298 | BJ15: 1309 | BK15: 1310 | BL15: 3347 | BM15: 3348 | BN15: 1379 | BO15: 1380 | BP15: 3397 | BQ15: 3398 | BR15: 1449 | BS15: 1450
A16: =Q16&S16 -> 207620 | B16: =E16&"."&F16&G16&"."&H16 -> J_TELE.14U0200.10 | C16: 13 | D16: 85_LPDP_ISP_FROM_TELE_RX_D1_CONN_P | E16: J_TELE | F16: 14 | G16: U0200 | H16: 10 | I16: =VLOOKUP(B16, vendor!$A$10:$Q$28,15,0) -> 1906.9279 | J16: =VLOOKUP(B16, vendor!$A$10:$Q$28,17,0) -> 1185.9061 | K16: =VLOOKUP(B16, vendor!$A$10:$Q$28,16,0) -> 3438.9502 | L16: 1530 | M16: 2655 | N16: 1530 | O16: 2655 | P16: 2075 | Q16: 2076 | R16: 19 | S16: 20 | T16: 2125 | U16: 2126 | V16: 89 | W16: 90 | X16: 2175 | Y16: 2176 | Z16: 159 | AA16: 160 | AB16: 2225 | AC16: 2226 | AD16: 229 | AE16: 230 | AF16: 2275 | AG16: 2276 | AH16: 299 | AI16: 300 | AJ16: 2325 | AK16: 2326 | AL16: 369 | AM16: 370 | AN16: 2375 | AO16: 2376 | AP16: 439 | AQ16: 440 | AR16: 3099 | AS16: 3100 | AT16: 1043 | AU16: 1044 | AV16: 3149 | AW16: 3150 | AX16: 1113 | AY16: 1114 | AZ16: 3199 | BA16: 3200 | BB16: 1183 | BC16: 1184 | BD16: 3249 | BE16: 3250 | BF16: 1253 | BG16: 1254 | BH16: 3299 | BI16: 3300 | BJ16: 1323 | BK16: 1324 | BL16: 3349 | BM16: 3350 | BN16: 1393 | BO16: 1394 | BP16: 3399 | BQ16: 3400 | BR16: 1463 | BS16: 1464
A17: =Q17&S17 -> 207810 | B17: =E17&"."&F17&G17&"."&H17 -> J_TELE.15U0200.5 | C17: 14 | D17: CLK_CAM_PMU1_TO_TELE_24M_1V8_CONN | E17: J_TELE | F17: 15 | G17: U0200 | H17: 5 | I17: =VLOOKUP(B17, vendor!$A$10:$Q$28,15,0) -> 1985.8283 | J17: =VLOOKUP(B17, vendor!$A$10:$Q$28,17,0) -> 1234.0543 | K17: =VLOOKUP(B17, vendor!$A$10:$Q$28,16,0) -> 3566.9959 | L17: 1587 | M17: 2614 | N17: 1587 | O17: 2614 | P17: 2077 | Q17: 2078 | R17: 9 | S17: 10 | T17: 2127 | U17: 2128 | V17: 79 | W17: 80 | X17: 2177 | Y17: 2178 | Z17: 149 | AA17: 150 | AB17: 2227 | AC17: 2228 | AD17: 219 | AE17: 220 | AF17: 2277 | AG17: 2278 | AH17: 289 | AI17: 290 | AJ17: 2327 | AK17: 2328 | AL17: 359 | AM17: 360 | AN17: 2377 | AO17: 2378 | AP17: 429 | AQ17: 430 | AR17: 3101 | AS17: 3102 | AT17: 1033 | AU17: 1034 | AV17: 3151 | AW17: 3152 | AX17: 1103 | AY17: 1104 | AZ17: 3201 | BA17: 3202 | BB17: 1173 | BC17: 1174 | BD17: 3251 | BE17: 3252 | BF17: 1243 | BG17: 1244 | BH17: 3301 | BI17: 3302 | BJ17: 1313 | BK17: 1314 | BL17: 3351 | BM17: 3352 | BN17: 1383 | BO17: 1384 | BP17: 3401 | BQ17: 3402 | BR17: 1453 | BS17: 1454
A18: =Q18&S18 -> 20828 | B18: =E18&"."&F18&G18&"."&H18 -> J_TELE.17U0200.4 | C18: 15 | D18: IO_RCAM_TO_MANY_SYNC_1V8 | E18: J_TELE | F18: 17 | G18: U0200 | H18: 4 | I18: =VLOOKUP(B18, vendor!$A$10:$Q$28,15,0) -> 2002.4622 | J18: =VLOOKUP(B18, vendor!$A$10:$Q$28,17,0) -> 1244.0363 | K18: =VLOOKUP(B18, vendor!$A$10:$Q$28,16,0) -> 3598.3501 | L18: 1616 | M18: 2660 | N18: 1616 | O18: 2660 | P18: 2081 | Q18: 2082 | R18: 7 | S18: 8 | T18: 2131 | U18: 2132 | V18: 77 | W18: 78 | X18: 2181 | Y18: 2182 | Z18: 147 | AA18: 148 | AB18: 2231 | AC18: 2232 | AD18: 217 | AE18: 218 | AF18: 2281 | AG18: 2282 | AH18: 287 | AI18: 288 | AJ18: 2331 | AK18: 2332 | AL18: 357 | AM18: 358 | AN18: 2381 | AO18: 2382 | AP18: 427 | AQ18: 428 | AR18: 3105 | AS18: 3106 | AT18: 1031 | AU18: 1032 | AV18: 3155 | AW18: 3156 | AX18: 1101 | AY18: 1102 | AZ18: 3205 | BA18: 3206 | BB18: 1171 | BC18: 1172 | BD18: 3255 | BE18: 3256 | BF18: 1241 | BG18: 1242 | BH18: 3305 | BI18: 3306 | BJ18: 1311 | BK18: 1312 | BL18: 3355 | BM18: 3356 | BN18: 1381 | BO18: 1382 | BP18: 3405 | BQ18: 3406 | BR18: 1451 | BS18: 1452
A19: =Q19&S19 -> 208416 | B19: =E19&"."&F19&G19&"."&H19 -> J_TELE.18U0200.8 | C19: 16 | D19: 85_LPDP_ISP_FROM_TELE_RX_D0_CONN_N | E19: J_TELE | F19: 18 | G19: U0200 | H19: 8 | I19: =VLOOKUP(B19, vendor!$A$10:$Q$28,15,0) -> 1904.1103 | J19: =VLOOKUP(B19, vendor!$A$10:$Q$28,17,0) -> 1183.7276 | K19: =VLOOKUP(B19, vendor!$A$10:$Q$28,16,0) -> 3433.8939 | L19: 1530 | M19: 2645 | N19: 1530 | O19: 2645 | P19: 2083 | Q19: 2084 | R19: 15 | S19: 16 | T19: 2133 | U19: 2134 | V19: 85 | W19: 86 | X19: 2183 | Y19: 2184 | Z19: 155 | AA19: 156 | AB19: 2233 | AC19: 2234 | AD19: 225 | AE19: 226 | AF19: 2283 | AG19: 2284 | AH19: 295 | AI19: 296 | AJ19: 2333 | AK19: 2334 | AL19: 365 | AM19: 366 | AN19: 2383 | AO19: 2384 | AP19: 435 | AQ19: 436 | AR19: 3107 | AS19: 3108 | AT19: 1039 | AU19: 1040 | AV19: 3157 | AW19: 3158 | AX19: 1109 | AY19: 1110 | AZ19: 3207 | BA19: 3208 | BB19: 1179 | BC19: 1180 | BD19: 3257 | BE19: 3258 | BF19: 1249 | BG19: 1250 | BH19: 3307 | BI19: 3308 | BJ19: 1319 | BK19: 1320 | BL19: 3357 | BM19: 3358 | BN19: 1389 | BO19: 1390 | BP19: 3407 | BQ19: 3408 | BR19: 1459 | BS19: 1460
A20: =Q20&S20 -> 20864 | B20: =E20&"."&F20&G20&"."&H20 -> J_TELE.19U0200.2 | C20: 17 | D20: PP1V32_TELE_DVDD_CONN | E20: J_TELE | F20: 19 | G20: U0200 | H20: 2 | I20: =VLOOKUP(B20, vendor!$A$10:$Q$28,15,0) -> 165.65865 | J20: =VLOOKUP(B20, vendor!$A$10:$Q$28,17,0) -> 125.38145 | K20: =VLOOKUP(B20, vendor!$A$10:$Q$28,16,0) -> 224.11051 | L20: 163 | M20: 187 | N20: 163 | O20: 187 | P20: 2085 | Q20: 2086 | R20: 3 | S20: 4 | T20: 2135 | U20: 2136 | V20: 73 | W20: 74 | X20: 2185 | Y20: 2186 | Z20: 143 | AA20: 144 | AB20: 2235 | AC20: 2236 | AD20: 213 | AE20: 214 | AF20: 2285 | AG20: 2286 | AH20: 283 | AI20: 284 | AJ20: 2335 | AK20: 2336 | AL20: 353 | AM20: 354 | AN20: 2385 | AO20: 2386 | AP20: 423 | AQ20: 424 | AR20: 3109 | AS20: 3110 | AT20: 1027 | AU20: 1028 | AV20: 3159 | AW20: 3160 | AX20: 1097 | AY20: 1098 | AZ20: 3209 | BA20: 3210 | BB20: 1167 | BC20: 1168 | BD20: 3259 | BE20: 3260 | BF20: 1237 | BG20: 1238 | BH20: 3309 | BI20: 3310 | BJ20: 1307 | BK20: 1308 | BL20: 3359 | BM20: 3360 | BN20: 1377 | BO20: 1378 | BP20: 3409 | BQ20: 3410 | BR20: 1447 | BS20: 1448
A21: =Q21&S21 -> 208814 | B21: =E21&"."&F21&G21&"."&H21 -> J_TELE.20U0200.7 | C21: 18 | D21: 85_LPDP_ISP_FROM_TELE_RX_D0_CONN_P | E21: J_TELE | F21: 20 | G21: U0200 | H21: 7 | I21: =VLOOKUP(B21, vendor!$A$10:$Q$28,15,0) -> 1904.408 | J21: =VLOOKUP(B21, vendor!$A$10:$Q$28,17,0) -> 1183.9721 | K21: =VLOOKUP(B21, vendor!$A$10:$Q$28,16,0) -> 3434.0656 | L21: 1527 | M21: 2654 | N21: 1527 | O21: 2654 | P21: 2087 | Q21: 2088 | R21: 13 | S21: 14 | T21: 2137 | U21: 2138 | V21: 83 | W21: 84 | X21: 2187 | Y21: 2188 | Z21: 153 | AA21: 154 | AB21: 2237 | AC21: 2238 | AD21: 223 | AE21: 224 | AF21: 2287 | AG21: 2288 | AH21: 293 | AI21: 294 | AJ21: 2337 | AK21: 2338 | AL21: 363 | AM21: 364 | AN21: 2387 | AO21: 2388 | AP21: 433 | AQ21: 434 | AR21: 3111 | AS21: 3112 | AT21: 1037 | AU21: 1038 | AV21: 3161 | AW21: 3162 | AX21: 1107 | AY21: 1108 | AZ21: 3211 | BA21: 3212 | BB21: 1177 | BC21: 1178 | BD21: 3261 | BE21: 3262 | BF21: 1247 | BG21: 1248 | BH21: 3311 | BI21: 3312 | BJ21: 1317 | BK21: 1318 | BL21: 3361 | BM21: 3362 | BN21: 1387 | BO21: 1388 | BP21: 3411 | BQ21: 3412 | BR21: 1457 | BS21: 1458
A22: =Q22&S22 -> 209052 | B22: =E22&"."&F22&G22&"."&H22 -> J_TELE.21U0200.26 | C22: 19 | D22: PPVAR_TELE_PVDD_OIS_CONN | E22: J_TELE | F22: 21 | G22: U0200 | H22: 26 | L22: 111 | M22: 130 | N22: 111 | O22: 130 | P22: 2089 | Q22: 2090 | R22: 51 | S22: 52 | T22: 2139 | U22: 2140 | V22: 121 | W22: 122 | X22: 2189 | Y22: 2190 | Z22: 191 | AA22: 192 | AB22: 2239 | AC22: 2240 | AD22: 261 | AE22: 262 | AF22: 2289 | AG22: 2290 | AH22: 331 | AI22: 332 | AJ22: 2339 | AK22: 2340 | AL22: 401 | AM22: 402 | AN22: 2389 | AO22: 2390 | AP22: 471 | AQ22: 472 | AR22: 3113 | AS22: 3114 | AT22: 1075 | AU22: 1076 | AV22: 3163 | AW22: 3164 | AX22: 1145 | AY22: 1146 | AZ22: 3213 | BA22: 3214 | BB22: 1215 | BC22: 1216 | BD22: 3263 | BE22: 3264 | BF22: 1285 | BG22: 1286 | BH22: 3313 | BI22: 3314 | BJ22: 1355 | BK22: 1356 | BL22: 3363 | BM22: 3364 | BN22: 1425 | BO22: 1426 | BP22: 3413 | BQ22: 3414 | BR22: 1495 | BS22: 1496
A23: =Q23&S23 -> 209252 | B23: =E23&"."&F23&G23&"."&H23 -> J_TELE.22U0200.26 | C23: 20 | D23: PPVAR_TELE_PVDD_OIS_CONN | E23: J_TELE | F23: 22 | G23: U0200 | H23: 26 | I23: =VLOOKUP(B23, vendor!$A$10:$Q$28,15,0) -> 115.83946 | J23: =VLOOKUP(B23, vendor!$A$10:$Q$28,17,0) -> 87.395468 | K23: =VLOOKUP(B23, vendor!$A$10:$Q$28,16,0) -> 157.18715 | L23: 112 | M23: 132 | N23: 112 | O23: 132 | P23: 2091 | Q23: 2092 | R23: 51 | S23: 52 | T23: 2141 | U23: 2142 | V23: 121 | W23: 122 | X23: 2191 | Y23: 2192 | Z23: 191 | AA23: 192 | AB23: 2241 | AC23: 2242 | AD23: 261 | AE23: 262 | AF23: 2291 | AG23: 2292 | AH23: 331 | AI23: 332 | AJ23: 2341 | AK23: 2342 | AL23: 401 | AM23: 402 | AN23: 2391 | AO23: 2392 | AP23: 471 | AQ23: 472 | AR23: 3115 | AS23: 3116 | AT23: 1075 | AU23: 1076 | AV23: 3165 | AW23: 3166 | AX23: 1145 | AY23: 1146 | AZ23: 3215 | BA23: 3216 | BB23: 1215 | BC23: 1216 | BD23: 3265 | BE23: 3266 | BF23: 1285 | BG23: 1286 | BH23: 3315 | BI23: 3316 | BJ23: 1355 | BK23: 1356 | BL23: 3365 | BM23: 3366 | BN23: 1425 | BO23: 1426 | BP23: 3415 | BQ23: 3416 | BR23: 1495 | BS23: 1496
A24: =Q24&S24 -> 20562 | B24: =E24&"."&F24&G24&"."&H24 -> J_TELE.4U0200.1 | C24: 21 | D24: GND | E24: J_TELE | F24: 4 | G24: U0200 | H24: 1 | L24: 17 | M24: 31 | N24: 17 | O24: 31 | P24: 2055 | Q24: 2056 | R24: 1 | S24: 2 | T24: 2105 | U24: 2106 | V24: 71 | W24: 72 | X24: 2155 | Y24: 2156 | Z24: 141 | AA24: 142 | AB24: 2205 | AC24: 2206 | AD24: 211 | AE24: 212 | AF24: 2255 | AG24: 2256 | AH24: 281 | AI24: 282 | AJ24: 2305 | AK24: 2306 | AL24: 351 | AM24: 352 | AN24: 2355 | AO24: 2356 | AP24: 421 | AQ24: 422 | AR24: 3079 | AS24: 3080 | AT24: 1025 | AU24: 1026 | AV24: 3129 | AW24: 3130 | AX24: 1095 | AY24: 1096 | AZ24: 3179 | BA24: 3180 | BB24: 1165 | BC24: 1166 | BD24: 3229 | BE24: 3230 | BF24: 1235 | BG24: 1236 | BH24: 3279 | BI24: 3280 | BJ24: 1305 | BK24: 1306 | BL24: 3329 | BM24: 3330 | BN24: 1375 | BO24: 1376 | BP24: 3379 | BQ24: 3380 | BR24: 1445 | BS24: 1446
A25: =Q25&S25 -> 205612 | B25: =E25&"."&F25&G25&"."&H25 -> J_TELE.4U0200.6 | C25: 22 | D25: GND | E25: J_TELE | F25: 4 | G25: U0200 | H25: 6 | L25: 16 | M25: 30 | N25: 16 | O25: 30 | P25: 2055 | Q25: 2056 | R25: 11 | S25: 12 | T25: 2105 | U25: 2106 | V25: 81 | W25: 82 | X25: 2155 | Y25: 2156 | Z25: 151 | AA25: 152 | AB25: 2205 | AC25: 2206 | AD25: 221 | AE25: 222 | AF25: 2255 | AG25: 2256 | AH25: 291 | AI25: 292 | AJ25: 2305 | AK25: 2306 | AL25: 361 | AM25: 362 | AN25: 2355 | AO25: 2356 | AP25: 431 | AQ25: 432 | AR25: 3079 | AS25: 3080 | AT25: 1035 | AU25: 1036 | AV25: 3129 | AW25: 3130 | AX25: 1105 | AY25: 1106 | AZ25: 3179 | BA25: 3180 | BB25: 1175 | BC25: 1176 | BD25: 3229 | BE25: 3230 | BF25: 1245 | BG25: 1246 | BH25: 3279 | BI25: 3280 | BJ25: 1315 | BK25: 1316 | BL25: 3329 | BM25: 3330 | BN25: 1385 | BO25: 1386 | BP25: 3379 | BQ25: 3380 | BR25: 1455 | BS25: 1456
A26: =Q26&S26 -> 205618 | B26: =E26&"."&F26&G26&"."&H26 -> J_TELE.4U0200.9 | C26: 23 | D26: GND | E26: J_TELE | F26: 4 | G26: U0200 | H26: 9 | L26: 16 | M26: 30 | N26: 16 | O26: 30 | P26: 2055 | Q26: 2056 | R26: 17 | S26: 18 | T26: 2105 | U26: 2106 | V26: 87 | W26: 88 | X26: 2155 | Y26: 2156 | Z26: 157 | AA26: 158 | AB26: 2205 | AC26: 2206 | AD26: 227 | AE26: 228 | AF26: 2255 | AG26: 2256 | AH26: 297 | AI26: 298 | AJ26: 2305 | AK26: 2306 | AL26: 367 | AM26: 368 | AN26: 2355 | AO26: 2356 | AP26: 437 | AQ26: 438 | AR26: 3079 | AS26: 3080 | AT26: 1041 | AU26: 1042 | AV26: 3129 | AW26: 3130 | AX26: 1111 | AY26: 1112 | AZ26: 3179 | BA26: 3180 | BB26: 1181 | BC26: 1182 | BD26: 3229 | BE26: 3230 | BF26: 1251 | BG26: 1252 | BH26: 3279 | BI26: 3280 | BJ26: 1321 | BK26: 1322 | BL26: 3329 | BM26: 3330 | BN26: 1391 | BO26: 1392 | BP26: 3379 | BQ26: 3380 | BR26: 1461 | BS26: 1462
A27: =Q27&S27 -> 205624 | B27: =E27&"."&F27&G27&"."&H27 -> J_TELE.4U0200.12 | C27: 24 | D27: GND | E27: J_TELE | F27: 4 | G27: U0200 | H27: 12 | L27: 16 | M27: 30 | N27: 16 | O27: 30 | P27: 2055 | Q27: 2056 | R27: 23 | S27: 24 | T27: 2105 | U27: 2106 | V27: 93 | W27: 94 | X27: 2155 | Y27: 2156 | Z27: 163 | AA27: 164 | AB27: 2205 | AC27: 2206 | AD27: 233 | AE27: 234 | AF27: 2255 | AG27: 2256 | AH27: 303 | AI27: 304 | AJ27: 2305 | AK27: 2306 | AL27: 373 | AM27: 374 | AN27: 2355 | AO27: 2356 | AP27: 443 | AQ27: 444 | AR27: 3079 | AS27: 3080 | AT27: 1047 | AU27: 1048 | AV27: 3129 | AW27: 3130 | AX27: 1117 | AY27: 1118 | AZ27: 3179 | BA27: 3180 | BB27: 1187 | BC27: 1188 | BD27: 3229 | BE27: 3230 | BF27: 1257 | BG27: 1258 | BH27: 3279 | BI27: 3280 | BJ27: 1327 | BK27: 1328 | BL27: 3329 | BM27: 3330 | BN27: 1397 | BO27: 1398 | BP27: 3379 | BQ27: 3380 | BR27: 1467 | BS27: 1468
A28: =Q28&S28 -> 205630 | B28: =E28&"."&F28&G28&"."&H28 -> J_TELE.4U0200.15 | C28: 25 | D28: GND | E28: J_TELE | F28: 4 | G28: U0200 | H28: 15 | L28: 16 | M28: 30 | N28: 16 | O28: 30 | P28: 2055 | Q28: 2056 | R28: 29 | S28: 30 | T28: 2105 | U28: 2106 | V28: 99 | W28: 100 | X28: 2155 | Y28: 2156 | Z28: 169 | AA28: 170 | AB28: 2205 | AC28: 2206 | AD28: 239 | AE28: 240 | AF28: 2255 | AG28: 2256 | AH28: 309 | AI28: 310 | AJ28: 2305 | AK28: 2306 | AL28: 379 | AM28: 380 | AN28: 2355 | AO28: 2356 | AP28: 449 | AQ28: 450 | AR28: 3079 | AS28: 3080 | AT28: 1053 | AU28: 1054 | AV28: 3129 | AW28: 3130 | AX28: 1123 | AY28: 1124 | AZ28: 3179 | BA28: 3180 | BB28: 1193 | BC28: 1194 | BD28: 3229 | BE28: 3230 | BF28: 1263 | BG28: 1264 | BH28: 3279 | BI28: 3280 | BJ28: 1333 | BK28: 1334 | BL28: 3329 | BM28: 3330 | BN28: 1403 | BO28: 1404 | BP28: 3379 | BQ28: 3380 | BR28: 1473 | BS28: 1474
A29: =Q29&S29 -> 205634 | B29: =E29&"."&F29&G29&"."&H29 -> J_TELE.4U0200.17 | C29: 26 | D29: GND | E29: J_TELE | F29: 4 | G29: U0200 | H29: 17 | L29: 17 | M29: 30 | N29: 17 | O29: 30 | P29: 2055 | Q29: 2056 | R29: 33 | S29: 34 | T29: 2105 | U29: 2106 | V29: 103 | W29: 104 | X29: 2155 | Y29: 2156 | Z29: 173 | AA29: 174 | AB29: 2205 | AC29: 2206 | AD29: 243 | AE29: 244 | AF29: 2255 | AG29: 2256 | AH29: 313 | AI29: 314 | AJ29: 2305 | AK29: 2306 | AL29: 383 | AM29: 384 | AN29: 2355 | AO29: 2356 | AP29: 453 | AQ29: 454 | AR29: 3079 | AS29: 3080 | AT29: 1057 | AU29: 1058 | AV29: 3129 | AW29: 3130 | AX29: 1127 | AY29: 1128 | AZ29: 3179 | BA29: 3180 | BB29: 1197 | BC29: 1198 | BD29: 3229 | BE29: 3230 | BF29: 1267 | BG29: 1268 | BH29: 3279 | BI29: 3280 | BJ29: 1337 | BK29: 1338 | BL29: 3329 | BM29: 3330 | BN29: 1407 | BO29: 1408 | BP29: 3379 | BQ29: 3380 | BR29: 1477 | BS29: 1478
A30: =Q30&S30 -> 205642 | B30: =E30&"."&F30&G30&"."&H30 -> J_TELE.4U0200.21 | C30: 27 | D30: GND | E30: J_TELE | F30: 4 | G30: U0200 | H30: 21 | L30: 17 | M30: 31 | N30: 17 | O30: 31 | P30: 2055 | Q30: 2056 | R30: 41 | S30: 42 | T30: 2105 | U30: 2106 | V30: 111 | W30: 112 | X30: 2155 | Y30: 2156 | Z30: 181 | AA30: 182 | AB30: 2205 | AC30: 2206 | AD30: 251 | AE30: 252 | AF30: 2255 | AG30: 2256 | AH30: 321 | AI30: 322 | AJ30: 2305 | AK30: 2306 | AL30: 391 | AM30: 392 | AN30: 2355 | AO30: 2356 | AP30: 461 | AQ30: 462 | AR30: 3079 | AS30: 3080 | AT30: 1065 | AU30: 1066 | AV30: 3129 | AW30: 3130 | AX30: 1135 | AY30: 1136 | AZ30: 3179 | BA30: 3180 | BB30: 1205 | BC30: 1206 | BD30: 3229 | BE30: 3230 | BF30: 1275 | BG30: 1276 | BH30: 3279 | BI30: 3280 | BJ30: 1345 | BK30: 1346 | BL30: 3329 | BM30: 3330 | BN30: 1415 | BO30: 1416 | BP30: 3379 | BQ30: 3380 | BR30: 1485 | BS30: 1486
A31: =Q31&S31 -> 205654 | B31: =E31&"."&F31&G31&"."&H31 -> J_TELE.4U0200.27 | C31: 28 | D31: GND | E31: J_TELE | F31: 4 | G31: U0200 | H31: 27 | L31: 18 | M31: 32 | N31: 18 | O31: 32 | P31: 2055 | Q31: 2056 | R31: 53 | S31: 54 | T31: 2105 | U31: 2106 | V31: 123 | W31: 124 | X31: 2155 | Y31: 2156 | Z31: 193 | AA31: 194 | AB31: 2205 | AC31: 2206 | AD31: 263 | AE31: 264 | AF31: 2255 | AG31: 2256 | AH31: 333 | AI31: 334 | AJ31: 2305 | AK31: 2306 | AL31: 403 | AM31: 404 | AN31: 2355 | AO31: 2356 | AP31: 473 | AQ31: 474 | AR31: 3079 | AS31: 3080 | AT31: 1077 | AU31: 1078 | AV31: 3129 | AW31: 3130 | AX31: 1147 | AY31: 1148 | AZ31: 3179 | BA31: 3180 | BB31: 1217 | BC31: 1218 | BD31: 3229 | BE31: 3230 | BF31: 1287 | BG31: 1288 | BH31: 3279 | BI31: 3280 | BJ31: 1357 | BK31: 1358 | BL31: 3329 | BM31: 3330 | BN31: 1427 | BO31: 1428 | BP31: 3379 | BQ31: 3380 | BR31: 1497 | BS31: 1498
A32: =Q32&S32 -> 206818 | B32: =E32&"."&F32&G32&"."&H32 -> J_TELE.10U0200.9 | C32: 29 | D32: GND | E32: J_TELE | F32: 10 | G32: U0200 | H32: 9 | L32: 16 | M32: 31 | N32: 16 | O32: 31 | P32: 2067 | Q32: 2068 | R32: 17 | S32: 18 | T32: 2117 | U32: 2118 | V32: 87 | W32: 88 | X32: 2167 | Y32: 2168 | Z32: 157 | AA32: 158 | AB32: 2217 | AC32: 2218 | AD32: 227 | AE32: 228 | AF32: 2267 | AG32: 2268 | AH32: 297 | AI32: 298 | AJ32: 2317 | AK32: 2318 | AL32: 367 | AM32: 368 | AN32: 2367 | AO32: 2368 | AP32: 437 | AQ32: 438 | AR32: 3091 | AS32: 3092 | AT32: 1041 | AU32: 1042 | AV32: 3141 | AW32: 3142 | AX32: 1111 | AY32: 1112 | AZ32: 3191 | BA32: 3192 | BB32: 1181 | BC32: 1182 | BD32: 3241 | BE32: 3242 | BF32: 1251 | BG32: 1252 | BH32: 3291 | BI32: 3292 | BJ32: 1321 | BK32: 1322 | BL32: 3341 | BM32: 3342 | BN32: 1391 | BO32: 1392 | BP32: 3391 | BQ32: 3392 | BR32: 1461 | BS32: 1462
A33: =Q33&S33 -> 206854 | B33: =E33&"."&F33&G33&"."&H33 -> J_TELE.10U0200.27 | C33: 30 | D33: GND | E33: J_TELE | F33: 10 | G33: U0200 | H33: 27 | I33: =VLOOKUP(B33, vendor!$A$10:$Q$28,15,0) -> 22.020308 | J33: =VLOOKUP(B33, vendor!$A$10:$Q$28,17,0) -> 15.854746 | K33: =VLOOKUP(B33, vendor!$A$10:$Q$28,16,0) -> 31.952898 | L33: 18 | M33: 31 | N33: 18 | O33: 31 | P33: 2067 | Q33: 2068 | R33: 53 | S33: 54 | T33: 2117 | U33: 2118 | V33: 123 | W33: 124 | X33: 2167 | Y33: 2168 | Z33: 193 | AA33: 194 | AB33: 2217 | AC33: 2218 | AD33: 263 | AE33: 264 | AF33: 2267 | AG33: 2268 | AH33: 333 | AI33: 334 | AJ33: 2317 | AK33: 2318 | AL33: 403 | AM33: 404 | AN33: 2367 | AO33: 2368 | AP33: 473 | AQ33: 474 | AR33: 3091 | AS33: 3092 | AT33: 1077 | AU33: 1078 | AV33: 3141 | AW33: 3142 | AX33: 1147 | AY33: 1148 | AZ33: 3191 | BA33: 3192 | BB33: 1217 | BC33: 1218 | BD33: 3241 | BE33: 3242 | BF33: 1287 | BG33: 1288 | BH33: 3291 | BI33: 3292 | BJ33: 1357 | BK33: 1358 | BL33: 3341 | BM33: 3342 | BN33: 1427 | BO33: 1428 | BP33: 3391 | BQ33: 3392 | BR33: 1497 | BS33: 1498
A34: =Q34&S34 -> 20802 | B34: =E34&"."&F34&G34&"."&H34 -> J_TELE.16U0200.1 | C34: 31 | D34: GND | E34: J_TELE | F34: 16 | G34: U0200 | H34: 1 | L34: 17 | M34: 32 | N34: 17 | O34: 32 | P34: 2079 | Q34: 2080 | R34: 1 | S34: 2 | T34: 2129 | U34: 2130 | V34: 71 | W34: 72 | X34: 2179 | Y34: 2180 | Z34: 141 | AA34: 142 | AB34: 2229 | AC34: 2230 | AD34: 211 | AE34: 212 | AF34: 2279 | AG34: 2280 | AH34: 281 | AI34: 282 | AJ34: 2329 | AK34: 2330 | AL34: 351 | AM34: 352 | AN34: 2379 | AO34: 2380 | AP34: 421 | AQ34: 422 | AR34: 3103 | AS34: 3104 | AT34: 1025 | AU34: 1026 | AV34: 3153 | AW34: 3154 | AX34: 1095 | AY34: 1096 | AZ34: 3203 | BA34: 3204 | BB34: 1165 | BC34: 1166 | BD34: 3253 | BE34: 3254 | BF34: 1235 | BG34: 1236 | BH34: 3303 | BI34: 3304 | BJ34: 1305 | BK34: 1306 | BL34: 3353 | BM34: 3354 | BN34: 1375 | BO34: 1376 | BP34: 3403 | BQ34: 3404 | BR34: 1445 | BS34: 1446
A35: =Q35&S35 -> 20942 | B35: =E35&"."&F35&G35&"."&H35 -> J_TELE.23U0200.1 | C35: 32 | D35: GND | E35: J_TELE | F35: 23 | G35: U0200 | H35: 1 | L35: 17 | M35: 30 | N35: 17 | O35: 30 | P35: 2093 | Q35: 2094 | R35: 1 | S35: 2 | T35: 2143 | U35: 2144 | V35: 71 | W35: 72 | X35: 2193 | Y35: 2194 | Z35: 141 | AA35: 142 | AB35: 2243 | AC35: 2244 | AD35: 211 | AE35: 212 | AF35: 2293 | AG35: 2294 | AH35: 281 | AI35: 282 | AJ35: 2343 | AK35: 2344 | AL35: 351 | AM35: 352 | AN35: 2393 | AO35: 2394 | AP35: 421 | AQ35: 422 | AR35: 3117 | AS35: 3118 | AT35: 1025 | AU35: 1026 | AV35: 3167 | AW35: 3168 | AX35: 1095 | AY35: 1096 | AZ35: 3217 | BA35: 3218 | BB35: 1165 | BC35: 1166 | BD35: 3267 | BE35: 3268 | BF35: 1235 | BG35: 1236 | BH35: 3317 | BI35: 3318 | BJ35: 1305 | BK35: 1306 | BL35: 3367 | BM35: 3368 | BN35: 1375 | BO35: 1376 | BP35: 3417 | BQ35: 3418 | BR35: 1445 | BS35: 1446
A36: =Q36&S36 -> 209612 | B36: =E36&"."&F36&G36&"."&H36 -> J_TELE.24U0200.6 | C36: 33 | D36: GND | E36: J_TELE | F36: 24 | G36: U0200 | H36: 6 | L36: 15 | M36: 29 | N36: 15 | O36: 29 | P36: 2095 | Q36: 2096 | R36: 11 | S36: 12 | T36: 2145 | U36: 2146 | V36: 81 | W36: 82 | X36: 2195 | Y36: 2196 | Z36: 151 | AA36: 152 | AB36: 2245 | AC36: 2246 | AD36: 221 | AE36: 222 | AF36: 2295 | AG36: 2296 | AH36: 291 | AI36: 292 | AJ36: 2345 | AK36: 2346 | AL36: 361 | AM36: 362 | AN36: 2395 | AO36: 2396 | AP36: 431 | AQ36: 432 | AR36: 3119 | AS36: 3120 | AT36: 1035 | AU36: 1036 | AV36: 3169 | AW36: 3170 | AX36: 1105 | AY36: 1106 | AZ36: 3219 | BA36: 3220 | BB36: 1175 | BC36: 1176 | BD36: 3269 | BE36: 3270 | BF36: 1245 | BG36: 1246 | BH36: 3319 | BI36: 3320 | BJ36: 1315 | BK36: 1316 | BL36: 3369 | BM36: 3370 | BN36: 1385 | BO36: 1386 | BP36: 3419 | BQ36: 3420 | BR36: 1455 | BS36: 1456
A37: =Q37&S37 -> 209656 | B37: =E37&"."&F37&G37&"."&H37 -> J_TELE.24SUS.41 | C37: 34 | D37: GND-SUS | E37: J_TELE | F37: 24 | G37: SUS | H37: 41 | L37: 0 | M37: 50 | N37: 0 | O37: 50 | P37: 2095 | Q37: 2096 | R37: 55 | S37: 56 | T37: 2145 | U37: 2146 | V37: 125 | W37: 126 | X37: 2195 | Y37: 2196 | Z37: 195 | AA37: 196 | AB37: 2245 | AC37: 2246 | AD37: 265 | AE37: 266 | AF37: 2295 | AG37: 2296 | AH37: 335 | AI37: 336 | AJ37: 2345 | AK37: 2346 | AL37: 405 | AM37: 406 | AN37: 2395 | AO37: 2396 | AP37: 475 | AQ37: 476 | AR37: 3119 | AS37: 3120 | AT37: 1079 | AU37: 1080 | AV37: 3169 | AW37: 3170 | AX37: 1149 | AY37: 1150 | AZ37: 3219 | BA37: 3220 | BB37: 1219 | BC37: 1220 | BD37: 3269 | BE37: 3270 | BF37: 1289 | BG37: 1290 | BH37: 3319 | BI37: 3320 | BJ37: 1359 | BK37: 1360 | BL37: 3369 | BM37: 3370 | BN37: 1429 | BO37: 1430 | BP37: 3419 | BQ37: 3420 | BR37: 1499 | BS37: 1500
A38: =Q38&S38
A39: =Q39&S39
A40: =Q40&S40
...

Sheet vendor
B2: Project | C2: 6Cxxx
B3: Design | C3: flex_rcam_6CRMEV
B4: Board | C4: 821-06056
B5: Version | C5: 2.0.0
B6: Vendor
B7: Date | C7: 09/10/2025
B9: Design | C9: APN | D9: Net Name | E9: Net Id | F9: Unique Net Id | G9: Pin 1 | H9: Pin 2 | I9: X1 | J9: Y1 | K9: Layer1 | L9: X2 | M9: Y2 | N9: Layer2 | O9: Nominal Sim (mΩ) | P9: USL (mΩ) | Q9: LSL (mΩ) | R9: Samples | S9: Min | T9: Max | U9: Mean | V9: Stdev
A10: =G10&H10 -> J_TELE.18U0200.8 | B10: 6Cxxx/flex_rcam_6CRMEV | C10: 821-06056 | D10: 85_LPDP_ISP_FROM_TELE_RX_D0_CONN_N | E10: 1 | F10: 821-06056_net1 | G10: J_TELE.18 | H10: U0200.8 | I10: 31.4311 | J10: -10.1907 | K10: BOTTOM | L10: 7.1341 | M10: -1.3121 | N10: ISL2 | O10: 1904.1103 | P10: 3433.8939 | Q10: 1183.7276 | R10: - | S10: - | T10: - | U10: - | V10: -
A11: =G11&H11 -> J_TELE.20U0200.7 | B11: 6Cxxx/flex_rcam_6CRMEV | C11: 821-06056 | D11: 85_LPDP_ISP_FROM_TELE_RX_D0_CONN_P | E11: 2 | F11: 821-06056_net2 | G11: J_TELE.20 | H11: U0200.7 | I11: 31.7311 | J11: -10.1907 | K11: BOTTOM | L11: 7.4841 | M11: -1.3121 | N11: ISL2 | O11: 1904.408 | P11: 3434.0656 | Q11: 1183.9721 | R11: - | S11: - | T11: - | U11: - | V11: -
A12: =G12&H12 -> J_TELE.12U0200.11 | B12: 6Cxxx/flex_rcam_6CRMEV | C12: 821-06056 | D12: 85_LPDP_ISP_FROM_TELE_RX_D1_CONN_N | E12: 3 | F12: 821-06056_net3 | G12: J_TELE.12 | H12: U0200.11 | I12: 30.5311 | J12: -10.1907 | K12: BOTTOM | L12: 6.0841 | M12: -1.3121 | N12: ISL2 | O12: 1907.3318 | P12: 3441.1932 | Q12: 1185.7905 | R12: - | S12: - | T12: - | U12: - | V12: -
A13: =G13&H13 -> J_TELE.14U0200.10 | B13: 6Cxxx/flex_rcam_6CRMEV | C13: 821-06056 | D13: 85_LPDP_ISP_FROM_TELE_RX_D1_CONN_P | E13: 4 | F13: 821-06056_net4 | G13: J_TELE.14 | H13: U0200.10 | I13: 30.8311 | J13: -10.1907 | K13: BOTTOM | L13: 6.4341 | M13: -1.3121 | N13: ISL2 | O13: 1906.9279 | P13: 3438.9502 | Q13: 1185.9061 | R13: - | S13: - | T13: - | U13: - | V13: -
A14: =G14&H14 -> J_TELE.6U0200.14 | B14: 6Cxxx/flex_rcam_6CRMEV | C14: 821-06056 | D14: 85_LPDP_ISP_FROM_TELE_RX_D2_CONN_N | E14: 5 | F14: 821-06056_net5 | G14: J_TELE.6 | H14: U0200.14 | I14: 29.6311 | J14: -10.1907 | K14: BOTTOM | L14: 5.0341 | M14: -1.3121 | N14: ISL2 | O14: 1934.3551 | P14: 3488.5586 | Q14: 1202.784 | R14: - | S14: - | T14: - | U14: - | V14: -
A15: =G15&H15 -> J_TELE.8U0200.13 | B15: 6Cxxx/flex_rcam_6CRMEV | C15: 821-06056 | D15: 85_LPDP_ISP_FROM_TELE_RX_D2_CONN_P | E15: 6 | F15: 821-06056_net6 | G15: J_TELE.8 | H15: U0200.13 | I15: 29.9311 | J15: -10.1907 | K15: BOTTOM | L15: 5.3841 | M15: -1.3121 | N15: ISL2 | O15: 1933.6592 | P15: 3486.518 | Q15: 1202.4945 | R15: - | S15: - | T15: - | U15: - | V15: -
A16: =G16&H16 -> J_TELE.15U0200.5 | B16: 6Cxxx/flex_rcam_6CRMEV | C16: 821-06056 | D16: CLK_CAM_PMU1_TO_TELE_24M_1V8_CONN | E16: 7 | F16: 821-06056_net7 | G16: J_TELE.15 | H16: U0200.5 | I16: 31.1311 | J16: -11.5807 | K16: BOTTOM | L16: 8.1841 | M16: -1.3121 | N16: ISL2 | O16: 1985.8283 | P16: 3566.9959 | Q16: 1234.0543 | R16: - | S16: - | T16: - | U16: - | V16: -
A17: =G17&H17 -> J_TELE.10U0200.27 | B17: 6Cxxx/flex_rcam_6CRMEV | C17: 821-06056 | D17: GND | E17: 8 | F17: 821-06056_net8 | G17: J_TELE.10 | H17: U0200.27 | I17: 30.2311 | J17: -10.1907 | K17: BOTTOM | L17: 0.4091 | M17: -1.2371 | N17: ISL2 | O17: 22.020308 | P17: 31.952898 | Q17: 15.854746 | R17: - | S17: - | T17: - | U17: - | V17: -
A18: =G18&H18 -> J_TELE.13U0200.3 | B18: 6Cxxx/flex_rcam_6CRMEV | C18: 821-06056 | D18: GPIO_CAM_PMU1_TO_TELE_SHDN_1V8_L | E18: 9 | F18: 821-06056_net9 | G18: J_TELE.13 | H18: U0200.3 | I18: 30.8311 | J18: -11.5807 | K18: BOTTOM | L18: 8.8841 | M18: -1.3121 | N18: ISL2 | O18: 2001.9336 | P18: 3592.6463 | Q18: 1244.4436 | R18: - | S18: - | T18: - | U18: - | V18: -
A19: =G19&H19 -> J_TELE.11U0200.16 | B19: 6Cxxx/flex_rcam_6CRMEV | C19: 821-06056 | D19: GPIO_CAMS_TO_STROBE_TRIGGER_1V8 | E19: 10 | F19: 821-06056_net10 | G19: J_TELE.11 | H19: U0200.16 | I19: 30.5311 | J19: -11.5807 | K19: BOTTOM | L19: 4.3341 | M19: -1.3121 | N19: ISL2 | O19: 1968.1463 | P19: 3534.787 | Q19: 1222.6648 | R19: - | S19: - | T19: - | U19: - | V19: -
A20: =G20&H20 -> J_TELE.2U0200.22 | B20: 6Cxxx/flex_rcam_6CRMEV | C20: 821-06056 | D20: I2C0_CAM_PMU2_SCL_1V8 | E20: 11 | F20: 821-06056_net11 | G20: J_TELE.2 | H20: U0200.22 | I20: 29.0311 | J20: -10.1907 | K20: BOTTOM | L20: 2.2341 | M20: -1.3121 | N20: ISL2 | O20: 1974.0056 | P20: 3547.1402 | Q20: 1226.8341 | R20: - | S20: - | T20: - | U20: - | V20: -
A21: =G21&H21 -> J_TELE.5U0200.23 | B21: 6Cxxx/flex_rcam_6CRMEV | C21: 821-06056 | D21: I2C0_CAM_PMU2_SDA_1V8 | E21: 12 | F21: 821-06056_net12 | G21: J_TELE.5 | H21: U0200.23 | I21: 29.6311 | J21: -11.5807 | K21: BOTTOM | L21: 1.8841 | M21: -1.3121 | N21: ISL2 | O21: 2033.4002 | P21: 3655.3378 | Q21: 1262.9662 | R21: - | S21: - | T21: - | U21: - | V21: -
... A28: =G28&H28 -> J_TELE.22U0200.26 | B28: 6Cxxx/flex_rcam_6CRMEV | C28: 821-06056 | D28: PPVAR_TELE_PVDD_OIS_CONN | E28: 19 | F28: 821-06056_net19 | G28: J_TELE.22 | H28: U0200.26 | I28: 28.6061 | J28: -10.3782 | K28: BOTTOM | L28: 0.8091 | M28: -1.2371 | N28: ISL2 | O28: 115.83946 | P28: 157.18715 | Q28: 87.395468 | R28: - | S28: - | T28: - | U28: - | V28: -

Sheet buyoff
A1: CHECK SHEET BUYOFF TEST COVERAGE ALL NET
A2: Iteam name: Item code: JIG NO: JIG MAKER:
A3: PE | B3: QA | C3: PRO | E3: RGO NET name and pin assign | J3: ERS spec | M3: 3 sigma spec | O3: On machine | Q3: our jig pin No
E4: Net name | F4: pin1 | H4: pin2 | J4: Nominal | K4: LSL | L4: USL | M4: LSL | N4: USL | O4: LSL | P4: USL | Q4: Gr1

Sheet pin
A51: #Gr02
A52: EXR4W | B52: 135 | C52: 136 | D52: 243 | E52: 244
A53: EXR4W | B53: 137 | C53: 138 | D53: 237 | E53: 238
A54: EXR4W | B54: 139 | C54: 140 | D54: 241 | E54: 242
A55: EXR4W | B55: 141 | C55: 142 | D55: 235 | E55: 236
A56: EXR4W | B56: 147 | C56: 148 | D56: 249 | E56: 250
A57: EXR4W | B57: 149 | C57: 150 | D57: 227 | E57: 228
A58: EXR4W | B58: 151 | C58: 152 | D58: 251 | E58: 252
A59: EXR4W | B59: 153 | C59: 154 | D59: 217 | E59: 218
A60: EXR4W | B60: 155 | C60: 156 | D60: 203 | E60: 204
A61: EXR4W | B61: 157 | C61: 158 | D61: 209 | E61: 210
A62: EXR4W | B62: 159 | C62: 160 | D62: 193 | E62: 194
A63: EXR4W | B63: 161 | C63: 162 | D63: 185 | E63: 186
... A100: EXR4W | B100: 169 | C100: 170 | D100: 175 | E100: 176
A102: #Gr03
A103: EXR4W | B103: 269 | C103: 270 | D103: 377 | E103: 378
A104: EXR4W | B104: 271 | C104: 272 | D104: 371 | E104: 372
A105: EXR4W | B105: 273 | C105: 274 | D105: 375 | E105: 376
A106: EXR4W | B106: 275 | C106: 276 | D106: 369 | E106: 370
A107: EXR4W | B107: 281 | C107: 282 | D107: 383 | E107: 384
A108: EXR4W | B108: 283 | C108: 284 | D108: 361 | E108: 362
A109: EXR4W | B109: 285 | C109: 286 | D109: 385 | E109: 386
A110: EXR4W | B110: 287 | C110: 288 | D110: 351 | E110: 352
A111: EXR4W | B111: 289 | C111: 290 | D111: 337 | E111: 338
A112: EXR4W | B112: 291 | C112: 292 | D112: 343 | E112: 344
A113: EXR4W | B113: 293 | C113: 294 | D113: 327 | E113: 328
A114: EXR4W | B114: 295 | C114: 296 | D114: 319 | E114: 320
... A151: EXR4W | B151: 303 | C151: 304 | D151: 309 | E151: 310
A153: #Gr04
A154: EXR4W | B154: 403 | C154: 404 | D154: 511 | E154: 512
A155: EXR4W | B155: 405 | C155: 406 | D155: 505 | E155: 506
A156: EXR4W | B156: 407 | C156: 408 | D156: 509 | E156: 510
A157: EXR4W | B157: 409 | C157: 410 | D157: 503 | E157: 504
A158: EXR4W | B158: 415 | C158: 416 | D158: 517 | E158: 518
A159: EXR4W | B159: 417 | C159: 418 | D159: 495 | E159: 496
A160: EXR4W | B160: 419 | C160: 420 | D160: 519 | E160: 520
A161: EXR4W | B161: 421 | C161: 422 | D161: 485 | E161: 486
A162: EXR4W | B162: 423 | C162: 424 | D162: 471 | E162: 472
A163: EXR4W | B163: 425 | C163: 426 | D163: 477 | E163: 478
A164: EXR4W | B164: 427 | C164: 428 | D164: 461 | E164: 462
...

Sheet Input check Pin 
A1: Input: Start Pin number each side | E1: J_FCAM | G1: U0200
E2: 1 | G2: 2049
B4: Group 1 | F4: Group 2 | J4: Group 3 | N4: Group 4 | R4: Group 5 | V4: Group 6 | Z4: Group 7 | AD4: Group 8 | AH4: Group 9 | AL4: Group 10 | AP4: Group 11 | AT4: Group 12 | AX4: Group 13 | BB4: Group 14 | BF4: Group 15 | BJ4: Group 16 | BN4: Group 17 | BR4: Group 18 | BV4: Group 19 | BZ4: Group 20 | CD4: Group 21 | CH4: Group 22 | CL4: Group 23 | CP4: Group 24 | CT4: Group 25
B5: J_FCAM | D5: U0200 | F5: J_FCAM | H5: U0200 | J5: J_FCAM | L5: U0200 | N5: J_FCAM | P5: U0200 | R5: J_FCAM | T5: U0200 | V5: J_FCAM | X5: U0200 | Z5: J_FCAM | AB5: U0200 | AD5: J_FCAM | AF5: U0200 | AH5: J_FCAM | AJ5: U0200 | AL5: J_FCAM | AN5: U0200 | AP5: J_FCAM | AR5: U0200 | AT5: J_FCAM | AV5: U0200 | AX5: J_FCAM | AZ5: U0200 | BB5: J_FCAM | BD5: U0200 | BF5: J_FCAM | BH5: U0200 | BJ5: J_FCAM | BL5: U0200 | BN5: J_FCAM | BP5: U0200 | BR5: J_FCAM | BT5: U0200 | BV5: J_FCAM | BX5: U0200 | BZ5: J_FCAM | CB5: U0200 | CD5: J_FCAM | CF5: U0200 | CH5: J_FCAM | CJ5: U0200 | CL5: J_FCAM | CN5: U0200 | CP5: J_FCAM | CR5: U0200 | CT5: J_FCAM | CV5: U0200
A6: Address | B6: 1 | C6: 70 | D6: 2049 | E6: 2098 | F6: 71 | G6: 140 | H6: 2099 | I6: 2148 | J6: 141 | K6: 210 | L6: 2149 | M6: 2198 | N6: 211 | O6: 280 | P6: 2199 | Q6: 2248 | R6: 281 | S6: 350 | T6: 2249 | U6: 2298 | V6: 351 | W6: 420 | X6: 2299 | Y6: 2348 | Z6: 421 | AA6: 490 | AB6: 2349 | AC6: 2398 | AD6: 1025 | AE6: 1094 | AF6: 3073 | AG6: 3122 | AH6: 1095 | AI6: 1164 | AJ6: 3123 | AK6: 3172 | AL6: 1165 | AM6: 1234 | AN6: 3173 | AO6: 3222 | AP6: 1235 | AQ6: 1304 | AR6: 3223 | AS6: 3272 | AT6: 1305 | AU6: 1374 | AV6: 3273 | AW6: 3322 | AX6: 1375 | AY6: 1444 | AZ6: 3323 | BA6: 3372 | BB6: 1445 | BC6: 1514 | BD6: 3373 | BE6: 3422
A7: Space | F7: =IF(F6="","",F6-B6) -> 70 | G7: =IF(G6="","",G6-C6) -> 70 | H7: =IF(H6="","",H6-D6) -> 50 | I7: =IF(I6="","",I6-E6) -> 50 | J7: =IF(J6="","",J6-F6) -> 70 | K7: =IF(K6="","",K6-G6) -> 70 | L7: =IF(L6="","",L6-H6) -> 50 | M7: =IF(M6="","",M6-I6) -> 50 | ... CW7: =IF(CW6="","",CW6-CS6)
A8: Judge | F8: =IF(OR(F7="",G7=""),"",IF(F7=G7,"OK","NG")) -> OK | H8: =IF(OR(H7="",I7=""),"",IF(H7=I7,"OK","NG")) -> OK | J8: =IF(OR(J7="",K7=""),"",IF(J7=K7,"OK","NG")) -> OK | L8: =IF(OR(L7="",M7=""),"",IF(L7=M7,"OK","NG")) -> OK | N8: =IF(OR(N7="",O7=""),"",IF(N7=O7,"OK","NG")) -> OK | P8: =IF(OR(P7="",Q7=""),"",IF(P7=Q7,"OK","NG")) -> OK | R8: =IF(OR(R7="",S7=""),"",IF(R7=S7,"OK","NG")) -> OK | T8: =IF(OR(T7="",U7=""),"",IF(T7=U7,"OK","NG")) -> OK | V8: =IF(OR(V7="",W7=""),"",IF(V7=W7,"OK","NG")) -> OK | X8: =IF(OR(X7="",Y7=""),"",IF(X7=Y7,"OK","NG")) -> OK | Z8: =IF(OR(Z7="",AA7=""),"",IF(Z7=AA7,"OK","NG")) -> OK | AB8: =IF(OR(AB7="",AC7=""),"",IF(AB7=AC7,"OK","NG")) -> OK | AD8: =IF(OR(AD7="",AE7=""),"",IF(AD7=AE7,"OK","NG")) -> OK | AF8: =IF(OR(AF7="",AG7=""),"",IF(AF7=AG7,"OK","NG")) -> OK | AH8: =IF(OR(AH7="",AI7=""),"",IF(AH7=AI7,"OK","NG")) -> OK | AJ8: =IF(OR(AJ7="",AK7=""),"",IF(AJ7=AK7,"OK","NG")) -> OK | AL8: =IF(OR(AL7="",AM7=""),"",IF(AL7=AM7,"OK","NG")) -> OK | AN8: =IF(OR(AN7="",AO7=""),"",IF(AN7=AO7,"OK","NG")) -> OK | AP8: =IF(OR(AP7="",AQ7=""),"",IF(AP7=AQ7,"OK","NG")) -> OK | AR8: =IF(OR(AR7="",AS7=""),"",IF(AR7=AS7,"OK","NG")) -> OK | AT8: =IF(OR(AT7="",AU7=""),"",IF(AT7=AU7,"OK","NG")) -> OK | AV8: =IF(OR(AV7="",AW7=""),"",IF(AV7=AW7,"OK","NG")) -> OK | AX8: =IF(OR(AX7="",AY7=""),"",IF(AX7=AY7,"OK","NG")) -> OK | AZ8: =IF(OR(AZ7="",BA7=""),"",IF(AZ7=BA7,"OK","NG")) -> OK | BB8: =IF(OR(BB7="",BC7=""),"",IF(BB7=BC7,"OK","NG")) -> OK | BD8: =IF(OR(BD7="",BE7=""),"",IF(BD7=BE7,"OK","NG")) -> OK | BF8: =IF(OR(BF7="",BG7=""),"",IF(BF7=BG7,"OK","NG")) | BH8: =IF(OR(BH7="",BI7=""),"",IF(BH7=BI7,"OK","NG")) | BJ8: =IF(OR(BJ7="",BK7=""),"",IF(BJ7=BK7,"OK","NG")) | BL8: =IF(OR(BL7="",BM7=""),"",IF(BL7=BM7,"OK","NG")) | BN8: =IF(OR(BN7="",BO7=""),"",IF(BN7=BO7,"OK","NG")) | BP8: =IF(OR(BP7="",BQ7=""),"",IF(BP7=BQ7,"OK","NG")) | BR8: =IF(OR(BR7="",BS7=""),"",IF(BR7=BS7,"OK","NG")) | BT8: =IF(OR(BT7="",BU7=""),"",IF(BT7=BU7,"OK","NG")) | BV8: =IF(OR(BV7="",BW7=""),"",IF(BV7=BW7,"OK","NG")) | BX8: =IF(OR(BX7="",BY7=""),"",IF(BX7=BY7,"OK","NG")) | BZ8: =IF(OR(BZ7="",CA7=""),"",IF(BZ7=CA7,"OK","NG")) | CB8: =IF(OR(CB7="",CC7=""),"",IF(CB7=CC7,"OK","NG")) | CD8: =IF(OR(CD7="",CE7=""),"",IF(CD7=CE7,"OK","NG")) | CF8: =IF(OR(CF7="",CG7=""),"",IF(CF7=CG7,"OK","NG")) | CH8: =IF(OR(CH7="",CI7=""),"",IF(CH7=CI7,"OK","NG")) | CJ8: =IF(OR(CJ7="",CK7=""),"",IF(CJ7=CK7,"OK","NG")) | CL8: =IF(OR(CL7="",CM7=""),"",IF(CL7=CM7,"OK","NG")) | CN8: =IF(OR(CN7="",CO7=""),"",IF(CN7=CO7,"OK","NG")) | CP8: =IF(OR(CP7="",CQ7=""),"",IF(CP7=CQ7,"OK","NG")) | CR8: =IF(OR(CR7="",CS7=""),"",IF(CR7=CS7,"OK","NG")) | CT8: =IF(OR(CT7="",CU7=""),"",IF(CT7=CU7,"OK","NG")) | CV8: =IF(OR(CV7="",CW7=""),"",IF(CV7=CW7,"OK","NG"))
A9: Select | F9: =IF(F8="OK",F7,) -> 70 | H9: =IF(H8="OK",H7,) -> 50 | J9: =IF(J8="OK",J7,) -> 70 | L9: =IF(L8="OK",L7,) -> 50 | N9: =IF(N8="OK",N7,) -> 70 | P9: =IF(P8="OK",P7,) -> 50 | R9: =IF(R8="OK",R7,) -> 70 | T9: =IF(T8="OK",T7,) -> 50 | V9: =IF(V8="OK",V7,) -> 70 | X9: =IF(X8="OK",X7,) -> 50 | Z9: =IF(Z8="OK",Z7,) -> 70 | AB9: =IF(AB8="OK",AB7,) -> 50 | AD9: =IF(AD8="OK",AD7,) -> 604 | AF9: =IF(AF8="OK",AF7,) -> 724 | AH9: =IF(AH8="OK",AH7,) -> 70 | AJ9: =IF(AJ8="OK",AJ7,) -> 50 | AL9: =IF(AL8="OK",AL7,) -> 70 | AN9: =IF(AN8="OK",AN7,) -> 50 | AP9: =IF(AP8="OK",AP7,) -> 70 | AR9: =IF(AR8="OK",AR7,) -> 50 | AT9: =IF(AT8="OK",AT7,) -> 70 | AV9: =IF(AV8="OK",AV7,) -> 50 | AX9: =IF(AX8="OK",AX7,) -> 70 | AZ9: =IF(AZ8="OK",AZ7,) -> 50 | BB9: =IF(BB8="OK",BB7,) -> 70 | BD9: =IF(BD8="OK",BD7,) -> 50 | BF9: =IF(BF8="OK",BF7,) -> 0 | BH9: =IF(BH8="OK",BH7,) -> 0 | BJ9: =IF(BJ8="OK",BJ7,) -> 0 | BL9: =IF(BL8="OK",BL7,) -> 0 | BN9: =IF(BN8="OK",BN7,) -> 0 | BP9: =IF(BP8="OK",BP7,) -> 0 | BR9: =IF(BR8="OK",BR7,) -> 0 | BT9: =IF(BT8="OK",BT7,) -> 0 | BV9: =IF(BV8="OK",BV7,) -> 0 | BX9: =IF(BX8="OK",BX7,) -> 0 | BZ9: =IF(BZ8="OK",BZ7,) -> 0 | CB9: =IF(CB8="OK",CB7,) -> 0 | CD9: =IF(CD8="OK",CD7,) -> 0 | CF9: =IF(CF8="OK",CF7,) -> 0 | CH9: =IF(CH8="OK",CH7,) -> 0 | CJ9: =IF(CJ8="OK",CJ7,) -> 0 | CL9: =IF(CL8="OK",CL7,) -> 0 | CN9: =IF(CN8="OK",CN7,) -> 0 | CP9: =IF(CP8="OK",CP7,) -> 0 | CR9: =IF(CR8="OK",CR7,) -> 0 | CT9: =IF(CT8="OK",CT7,) -> 0 | CV9: =IF(CV8="OK",CV7,) -> 0
B11: Automatic calculation | CX11: Maker data
A12: NO | B12: Group 1 | F12: Group 2 | J12: Group 3 | N12: Group 4 | R12: Group 5 | V12: Group 6 | Z12: Group 7 | AD12: Group 8 | AH12: Group 9 | AL12: Group 10 | AP12: Group 11 | AT12: Group 12 | AX12: Group 13 | BB12: Group 14 | BF12: Group 15 | BJ12: Group 16 | BN12: Group 17 | BR12: Group 18 | BV12: Group 19 | BZ12: Group 20 | CD12: Group 21 | CH12: Group 22 | CL12: Group 23 | CP12: Group 24 | CT12: Group 25 | CX12: Group 1 | DB12: Group 2 | DF12: Group 3 | DJ12: Group 4 | DN12: Group 5 | DR12: Group 6 | DV12: Group 7 | DZ12: Group 8 | ED12: Group 9 | EH12: Group 10 | EL12: Group 11 | EP12: Group 12 | ET12: Group 13 | EX12: Group 14 | FB12: Group 15 | FF12: Group 16 | FJ12: Group 17 | FN12: Group 18 | FR12: Group 19 | FV12: Group 20 | FZ12: Group 21 | GD12: Group 22 | GH12: Group 23 | GL12: Group 24 | GP12: Group 25
